[2024-03-20T21:01:51.904+0000] {logging_mixin.py:154} INFO - Changing /opt/***/logs/dag_id=dag_carbon_intensity/run_id=scheduled__2024-03-16T00:00:00+00:00/task_id=create_table_task permission to 509
[2024-03-20T21:10:55.551+0000] {logging_mixin.py:154} INFO - Changing /opt/***/logs/dag_id=dag_carbon_intensity/run_id=scheduled__2024-03-16T00:00:00+00:00/task_id=create_table_task permission to 509
[2024-03-20T21:11:01.664+0000] {logging_mixin.py:154} INFO - Changing /opt/***/logs/dag_id=dag_carbon_intensity/run_id=scheduled__2024-03-16T00:00:00+00:00/task_id=create_table_task permission to 509
[2024-03-20T21:11:08.627+0000] {taskinstance.py:1159} INFO - Dependencies all met for dep_context=non-requeueable deps ti=<TaskInstance: dag_carbon_intensity.create_table_task scheduled__2024-03-16T00:00:00+00:00 [queued]>
[2024-03-20T21:11:08.983+0000] {taskinstance.py:1159} INFO - Dependencies all met for dep_context=requeueable deps ti=<TaskInstance: dag_carbon_intensity.create_table_task scheduled__2024-03-16T00:00:00+00:00 [queued]>
[2024-03-20T21:11:08.992+0000] {taskinstance.py:1361} INFO - Starting attempt 2 of 4
[2024-03-20T21:11:42.870+0000] {local_task_job_runner.py:115} ERROR - Received SIGTERM. Terminating subprocesses
[2024-03-20T21:11:43.015+0000] {local_task_job_runner.py:228} INFO - Task exited with return code 143
[2024-03-20T21:11:43.367+0000] {taskinstance.py:2784} INFO - Skipping mini scheduling run due to exception: SELECT dag_run.state AS dag_run_state, dag_run.id AS dag_run_id, dag_run.dag_id AS dag_run_dag_id, dag_run.queued_at AS dag_run_queued_at, dag_run.execution_date AS dag_run_execution_date, dag_run.start_date AS dag_run_start_date, dag_run.end_date AS dag_run_end_date, dag_run.run_id AS dag_run_run_id, dag_run.creating_job_id AS dag_run_creating_job_id, dag_run.external_trigger AS dag_run_external_trigger, dag_run.run_type AS dag_run_run_type, dag_run.conf AS dag_run_conf, dag_run.data_interval_start AS dag_run_data_interval_start, dag_run.data_interval_end AS dag_run_data_interval_end, dag_run.last_scheduling_decision AS dag_run_last_scheduling_decision, dag_run.dag_hash AS dag_run_dag_hash, dag_run.log_template_id AS dag_run_log_template_id, dag_run.updated_at AS dag_run_updated_at 
FROM dag_run 
WHERE dag_run.dag_id = %(dag_id_1)s AND dag_run.run_id = %(run_id_1)s FOR UPDATE
Traceback (most recent call last):
  File "/home/airflow/.local/lib/python3.8/site-packages/sqlalchemy/engine/base.py", line 1910, in _execute_context
    self.dialect.do_execute(
  File "/home/airflow/.local/lib/python3.8/site-packages/sqlalchemy/engine/default.py", line 736, in do_execute
    cursor.execute(statement, parameters)
psycopg2.OperationalError

The above exception was the direct cause of the following exception:

Traceback (most recent call last):
  File "/home/airflow/.local/lib/python3.8/site-packages/airflow/models/taskinstance.py", line 2733, in schedule_downstream_tasks
    dag_run = with_row_locks(
  File "/home/airflow/.local/lib/python3.8/site-packages/sqlalchemy/orm/query.py", line 2870, in one
    return self._iter().one()
  File "/home/airflow/.local/lib/python3.8/site-packages/sqlalchemy/orm/query.py", line 2916, in _iter
    result = self.session.execute(
  File "/home/airflow/.local/lib/python3.8/site-packages/sqlalchemy/orm/session.py", line 1717, in execute
    result = conn._execute_20(statement, params or {}, execution_options)
  File "/home/airflow/.local/lib/python3.8/site-packages/sqlalchemy/engine/base.py", line 1710, in _execute_20
    return meth(self, args_10style, kwargs_10style, execution_options)
  File "/home/airflow/.local/lib/python3.8/site-packages/sqlalchemy/sql/elements.py", line 334, in _execute_on_connection
    return connection._execute_clauseelement(
  File "/home/airflow/.local/lib/python3.8/site-packages/sqlalchemy/engine/base.py", line 1577, in _execute_clauseelement
    ret = self._execute_context(
  File "/home/airflow/.local/lib/python3.8/site-packages/sqlalchemy/engine/base.py", line 1953, in _execute_context
    self._handle_dbapi_exception(
  File "/home/airflow/.local/lib/python3.8/site-packages/sqlalchemy/engine/base.py", line 2134, in _handle_dbapi_exception
    util.raise_(
  File "/home/airflow/.local/lib/python3.8/site-packages/sqlalchemy/util/compat.py", line 211, in raise_
    raise exception
  File "/home/airflow/.local/lib/python3.8/site-packages/sqlalchemy/engine/base.py", line 1910, in _execute_context
    self.dialect.do_execute(
  File "/home/airflow/.local/lib/python3.8/site-packages/sqlalchemy/engine/default.py", line 736, in do_execute
    cursor.execute(statement, parameters)
sqlalchemy.exc.OperationalError: (psycopg2.OperationalError) 
[SQL: SELECT dag_run.state AS dag_run_state, dag_run.id AS dag_run_id, dag_run.dag_id AS dag_run_dag_id, dag_run.queued_at AS dag_run_queued_at, dag_run.execution_date AS dag_run_execution_date, dag_run.start_date AS dag_run_start_date, dag_run.end_date AS dag_run_end_date, dag_run.run_id AS dag_run_run_id, dag_run.creating_job_id AS dag_run_creating_job_id, dag_run.external_trigger AS dag_run_external_trigger, dag_run.run_type AS dag_run_run_type, dag_run.conf AS dag_run_conf, dag_run.data_interval_start AS dag_run_data_interval_start, dag_run.data_interval_end AS dag_run_data_interval_end, dag_run.last_scheduling_decision AS dag_run_last_scheduling_decision, dag_run.dag_hash AS dag_run_dag_hash, dag_run.log_template_id AS dag_run_log_template_id, dag_run.updated_at AS dag_run_updated_at 
FROM dag_run 
WHERE dag_run.dag_id = %(dag_id_1)s AND dag_run.run_id = %(run_id_1)s FOR UPDATE]
[parameters: {'dag_id_1': 'dag_carbon_intensity', 'run_id_1': 'scheduled__2024-03-16T00:00:00+00:00'}]
(Background on this error at: https://sqlalche.me/e/14/e3q8)
