[2024-03-10T16:41:53.265+0000] {logging_mixin.py:154} INFO - Changing /opt/***/logs/dag_id=dag_carbon_intensity/run_id=manual__2024-03-10T16:41:47.859175+00:00/task_id=create_table_task permission to 509
[2024-03-10T16:41:53.826+0000] {logging_mixin.py:154} INFO - Changing /opt/***/logs/dag_id=dag_carbon_intensity/run_id=manual__2024-03-10T16:41:47.859175+00:00/task_id=create_table_task permission to 509
[2024-03-10T16:41:53.934+0000] {taskinstance.py:1159} INFO - Dependencies all met for dep_context=non-requeueable deps ti=<TaskInstance: dag_carbon_intensity.create_table_task manual__2024-03-10T16:41:47.859175+00:00 [queued]>
[2024-03-10T16:41:53.950+0000] {taskinstance.py:1159} INFO - Dependencies all met for dep_context=requeueable deps ti=<TaskInstance: dag_carbon_intensity.create_table_task manual__2024-03-10T16:41:47.859175+00:00 [queued]>
[2024-03-10T16:41:53.952+0000] {taskinstance.py:1361} INFO - Starting attempt 1 of 4
[2024-03-10T16:41:53.980+0000] {taskinstance.py:1382} INFO - Executing <Task(PostgresOperator): create_table_task> on 2024-03-10 16:41:47.859175+00:00
[2024-03-10T16:41:53.995+0000] {standard_task_runner.py:57} INFO - Started process 8753 to run task
[2024-03-10T16:41:54.014+0000] {standard_task_runner.py:84} INFO - Running: ['***', 'tasks', 'run', 'dag_carbon_intensity', 'create_table_task', 'manual__2024-03-10T16:41:47.859175+00:00', '--job-id', '155', '--raw', '--subdir', 'DAGS_FOLDER/dag_carbon_intensity.py', '--cfg-path', '/tmp/tmpcyddcawe']
[2024-03-10T16:41:54.032+0000] {standard_task_runner.py:85} INFO - Job 155: Subtask create_table_task
[2024-03-10T16:41:54.288+0000] {logging_mixin.py:154} INFO - Changing /opt/***/logs/dag_id=dag_carbon_intensity/run_id=manual__2024-03-10T16:41:47.859175+00:00/task_id=create_table_task permission to 509
[2024-03-10T16:41:54.333+0000] {task_command.py:416} INFO - Running <TaskInstance: dag_carbon_intensity.create_table_task manual__2024-03-10T16:41:47.859175+00:00 [running]> on host b90b2ddba1ac
[2024-03-10T16:41:54.853+0000] {taskinstance.py:1662} INFO - Exporting env vars: AIRFLOW_CTX_DAG_OWNER='***' AIRFLOW_CTX_DAG_ID='dag_carbon_intensity' AIRFLOW_CTX_TASK_ID='create_table_task' AIRFLOW_CTX_EXECUTION_DATE='2024-03-10T16:41:47.859175+00:00' AIRFLOW_CTX_TRY_NUMBER='1' AIRFLOW_CTX_DAG_RUN_ID='manual__2024-03-10T16:41:47.859175+00:00'
[2024-03-10T16:41:54.862+0000] {sql.py:274} INFO - Executing: CREATE TABLE IF NOT EXISTS craverolucio_coderhouse.carbon_intensity (
    from_date VARCHAR(50) PRIMARY KEY,
    to_date VARCHAR(50) SORTKEY,
    intensity_max SMALLINT,
    intensity_average SMALLINT,
    intensity_min SMALLINT,
    intensity_index VARCHAR(50)
);
[2024-03-10T16:41:54.917+0000] {base.py:73} INFO - Using connection ID 'coderhouse_redshift' for task execution.
[2024-03-10T16:41:55.954+0000] {base.py:73} INFO - Using connection ID 'coderhouse_redshift' for task execution.
[2024-03-10T16:41:59.303+0000] {sql.py:418} INFO - Running statement: CREATE TABLE IF NOT EXISTS craverolucio_coderhouse.carbon_intensity (
    from_date VARCHAR(50) PRIMARY KEY,
    to_date VARCHAR(50) SORTKEY,
    intensity_max SMALLINT,
    intensity_average SMALLINT,
    intensity_min SMALLINT,
    intensity_index VARCHAR(50)
);, parameters: None
[2024-03-10T16:42:10.730+0000] {job.py:219} ERROR - Job heartbeat got an exception
Traceback (most recent call last):
  File "/home/airflow/.local/lib/python3.8/site-packages/sqlalchemy/engine/base.py", line 3371, in _wrap_pool_connect
    return fn()
  File "/home/airflow/.local/lib/python3.8/site-packages/sqlalchemy/pool/base.py", line 327, in connect
    return _ConnectionFairy._checkout(self)
  File "/home/airflow/.local/lib/python3.8/site-packages/sqlalchemy/pool/base.py", line 894, in _checkout
    fairy = _ConnectionRecord.checkout(pool)
  File "/home/airflow/.local/lib/python3.8/site-packages/sqlalchemy/pool/base.py", line 493, in checkout
    rec = pool._do_get()
  File "/home/airflow/.local/lib/python3.8/site-packages/sqlalchemy/pool/impl.py", line 256, in _do_get
    return self._create_connection()
  File "/home/airflow/.local/lib/python3.8/site-packages/sqlalchemy/pool/base.py", line 273, in _create_connection
    return _ConnectionRecord(self)
  File "/home/airflow/.local/lib/python3.8/site-packages/sqlalchemy/pool/base.py", line 388, in __init__
    self.__connect()
  File "/home/airflow/.local/lib/python3.8/site-packages/sqlalchemy/pool/base.py", line 691, in __connect
    pool.logger.debug("Error on connect(): %s", e)
  File "/home/airflow/.local/lib/python3.8/site-packages/sqlalchemy/util/langhelpers.py", line 70, in __exit__
    compat.raise_(
  File "/home/airflow/.local/lib/python3.8/site-packages/sqlalchemy/util/compat.py", line 211, in raise_
    raise exception
  File "/home/airflow/.local/lib/python3.8/site-packages/sqlalchemy/pool/base.py", line 686, in __connect
    self.dbapi_connection = connection = pool._invoke_creator(self)
  File "/home/airflow/.local/lib/python3.8/site-packages/sqlalchemy/engine/create.py", line 574, in connect
    return dialect.connect(*cargs, **cparams)
  File "/home/airflow/.local/lib/python3.8/site-packages/sqlalchemy/engine/default.py", line 598, in connect
    return self.dbapi.connect(*cargs, **cparams)
  File "/home/airflow/.local/lib/python3.8/site-packages/psycopg2/__init__.py", line 122, in connect
    conn = _connect(dsn, connection_factory=connection_factory, **kwasync)
psycopg2.OperationalError: could not translate host name "postgres" to address: Temporary failure in name resolution


The above exception was the direct cause of the following exception:

Traceback (most recent call last):
  File "/home/airflow/.local/lib/python3.8/site-packages/airflow/jobs/job.py", line 215, in heartbeat
    heartbeat_callback(session)
  File "/home/airflow/.local/lib/python3.8/site-packages/airflow/utils/session.py", line 76, in wrapper
    return func(*args, **kwargs)
  File "/home/airflow/.local/lib/python3.8/site-packages/airflow/jobs/local_task_job_runner.py", line 246, in heartbeat_callback
    self.task_instance.refresh_from_db()
  File "/home/airflow/.local/lib/python3.8/site-packages/airflow/utils/session.py", line 79, in wrapper
    return func(*args, session=session, **kwargs)
  File "/home/airflow/.local/lib/python3.8/site-packages/airflow/models/taskinstance.py", line 866, in refresh_from_db
    ti = qry.one_or_none()
  File "/home/airflow/.local/lib/python3.8/site-packages/sqlalchemy/orm/query.py", line 2850, in one_or_none
    return self._iter().one_or_none()
  File "/home/airflow/.local/lib/python3.8/site-packages/sqlalchemy/orm/query.py", line 2916, in _iter
    result = self.session.execute(
  File "/home/airflow/.local/lib/python3.8/site-packages/sqlalchemy/orm/session.py", line 1716, in execute
    conn = self._connection_for_bind(bind)
  File "/home/airflow/.local/lib/python3.8/site-packages/sqlalchemy/orm/session.py", line 1555, in _connection_for_bind
    return self._transaction._connection_for_bind(
  File "/home/airflow/.local/lib/python3.8/site-packages/sqlalchemy/orm/session.py", line 750, in _connection_for_bind
    conn = bind.connect()
  File "/home/airflow/.local/lib/python3.8/site-packages/sqlalchemy/future/engine.py", line 406, in connect
    return super(Engine, self).connect()
  File "/home/airflow/.local/lib/python3.8/site-packages/sqlalchemy/engine/base.py", line 3325, in connect
    return self._connection_cls(self, close_with_result=close_with_result)
  File "/home/airflow/.local/lib/python3.8/site-packages/sqlalchemy/engine/base.py", line 96, in __init__
    else engine.raw_connection()
  File "/home/airflow/.local/lib/python3.8/site-packages/sqlalchemy/engine/base.py", line 3404, in raw_connection
    return self._wrap_pool_connect(self.pool.connect, _connection)
  File "/home/airflow/.local/lib/python3.8/site-packages/sqlalchemy/engine/base.py", line 3374, in _wrap_pool_connect
    Connection._handle_dbapi_exception_noconnection(
  File "/home/airflow/.local/lib/python3.8/site-packages/sqlalchemy/engine/base.py", line 2208, in _handle_dbapi_exception_noconnection
    util.raise_(
  File "/home/airflow/.local/lib/python3.8/site-packages/sqlalchemy/util/compat.py", line 211, in raise_
    raise exception
  File "/home/airflow/.local/lib/python3.8/site-packages/sqlalchemy/engine/base.py", line 3371, in _wrap_pool_connect
    return fn()
  File "/home/airflow/.local/lib/python3.8/site-packages/sqlalchemy/pool/base.py", line 327, in connect
    return _ConnectionFairy._checkout(self)
  File "/home/airflow/.local/lib/python3.8/site-packages/sqlalchemy/pool/base.py", line 894, in _checkout
    fairy = _ConnectionRecord.checkout(pool)
  File "/home/airflow/.local/lib/python3.8/site-packages/sqlalchemy/pool/base.py", line 493, in checkout
    rec = pool._do_get()
  File "/home/airflow/.local/lib/python3.8/site-packages/sqlalchemy/pool/impl.py", line 256, in _do_get
    return self._create_connection()
  File "/home/airflow/.local/lib/python3.8/site-packages/sqlalchemy/pool/base.py", line 273, in _create_connection
    return _ConnectionRecord(self)
  File "/home/airflow/.local/lib/python3.8/site-packages/sqlalchemy/pool/base.py", line 388, in __init__
    self.__connect()
  File "/home/airflow/.local/lib/python3.8/site-packages/sqlalchemy/pool/base.py", line 691, in __connect
    pool.logger.debug("Error on connect(): %s", e)
  File "/home/airflow/.local/lib/python3.8/site-packages/sqlalchemy/util/langhelpers.py", line 70, in __exit__
    compat.raise_(
  File "/home/airflow/.local/lib/python3.8/site-packages/sqlalchemy/util/compat.py", line 211, in raise_
    raise exception
  File "/home/airflow/.local/lib/python3.8/site-packages/sqlalchemy/pool/base.py", line 686, in __connect
    self.dbapi_connection = connection = pool._invoke_creator(self)
  File "/home/airflow/.local/lib/python3.8/site-packages/sqlalchemy/engine/create.py", line 574, in connect
    return dialect.connect(*cargs, **cparams)
  File "/home/airflow/.local/lib/python3.8/site-packages/sqlalchemy/engine/default.py", line 598, in connect
    return self.dbapi.connect(*cargs, **cparams)
  File "/home/airflow/.local/lib/python3.8/site-packages/psycopg2/__init__.py", line 122, in connect
    conn = _connect(dsn, connection_factory=connection_factory, **kwasync)
sqlalchemy.exc.OperationalError: (psycopg2.OperationalError) could not translate host name "postgres" to address: Temporary failure in name resolution

(Background on this error at: https://sqlalche.me/e/14/e3q8)
[2024-03-10T16:42:29.741+0000] {taskinstance.py:1400} INFO - Marking task as SUCCESS. dag_id=dag_carbon_intensity, task_id=create_table_task, execution_date=20240310T164147, start_date=20240310T164153, end_date=20240310T164229
[2024-03-10T16:42:31.258+0000] {local_task_job_runner.py:228} INFO - Task exited with return code 0
[2024-03-10T16:42:31.325+0000] {taskinstance.py:2778} INFO - 0 downstream tasks scheduled from follow-on schedule check
