[2024-03-20T21:32:45.066+0000] {logging_mixin.py:154} INFO - Changing /opt/***/logs/dag_id=dag_carbon_intensity/run_id=scheduled__2024-03-18T00:00:00+00:00/task_id=create_stage_table_task permission to 509
[2024-03-20T21:32:45.233+0000] {logging_mixin.py:154} INFO - Changing /opt/***/logs/dag_id=dag_carbon_intensity/run_id=scheduled__2024-03-18T00:00:00+00:00/task_id=create_stage_table_task permission to 509
[2024-03-20T21:32:45.341+0000] {taskinstance.py:1159} INFO - Dependencies all met for dep_context=non-requeueable deps ti=<TaskInstance: dag_carbon_intensity.create_stage_table_task scheduled__2024-03-18T00:00:00+00:00 [queued]>
[2024-03-20T21:32:45.372+0000] {taskinstance.py:1159} INFO - Dependencies all met for dep_context=requeueable deps ti=<TaskInstance: dag_carbon_intensity.create_stage_table_task scheduled__2024-03-18T00:00:00+00:00 [queued]>
[2024-03-20T21:32:45.384+0000] {taskinstance.py:1361} INFO - Starting attempt 1 of 4
[2024-03-20T21:32:45.442+0000] {taskinstance.py:1382} INFO - Executing <Task(PostgresOperator): create_stage_table_task> on 2024-03-18 00:00:00+00:00
[2024-03-20T21:32:45.453+0000] {standard_task_runner.py:57} INFO - Started process 173 to run task
[2024-03-20T21:32:45.456+0000] {standard_task_runner.py:84} INFO - Running: ['***', 'tasks', 'run', 'dag_carbon_intensity', 'create_stage_table_task', 'scheduled__2024-03-18T00:00:00+00:00', '--job-id', '339', '--raw', '--subdir', 'DAGS_FOLDER/dag_carbon_intensity.py', '--cfg-path', '/tmp/tmpn1zfqk7w']
[2024-03-20T21:32:45.460+0000] {standard_task_runner.py:85} INFO - Job 339: Subtask create_stage_table_task
[2024-03-20T21:32:45.687+0000] {logging_mixin.py:154} INFO - Changing /opt/***/logs/dag_id=dag_carbon_intensity/run_id=scheduled__2024-03-18T00:00:00+00:00/task_id=create_stage_table_task permission to 509
[2024-03-20T21:32:45.728+0000] {task_command.py:416} INFO - Running <TaskInstance: dag_carbon_intensity.create_stage_table_task scheduled__2024-03-18T00:00:00+00:00 [running]> on host aa33b9d375a5
[2024-03-20T21:32:46.026+0000] {taskinstance.py:1662} INFO - Exporting env vars: AIRFLOW_CTX_DAG_OWNER='***' AIRFLOW_CTX_DAG_ID='dag_carbon_intensity' AIRFLOW_CTX_TASK_ID='create_stage_table_task' AIRFLOW_CTX_EXECUTION_DATE='2024-03-18T00:00:00+00:00' AIRFLOW_CTX_TRY_NUMBER='1' AIRFLOW_CTX_DAG_RUN_ID='scheduled__2024-03-18T00:00:00+00:00'
[2024-03-20T21:32:46.035+0000] {sql.py:274} INFO - Executing: CREATE TABLE IF NOT EXISTS craverolucio_coderhouse.carbon_intensity_stg (
    from_date VARCHAR(50) PRIMARY KEY,
    to_date VARCHAR(50) SORTKEY,
    intensity_max SMALLINT,
    intensity_average SMALLINT,
    intensity_min SMALLINT,
    intensity_index VARCHAR(50)
);
[2024-03-20T21:32:46.074+0000] {base.py:73} INFO - Using connection ID 'coderhouse_redshift' for task execution.
[2024-03-20T21:32:56.953+0000] {base.py:73} INFO - Using connection ID 'coderhouse_redshift' for task execution.
[2024-03-20T21:33:15.218+0000] {sql.py:418} INFO - Running statement: CREATE TABLE IF NOT EXISTS craverolucio_coderhouse.carbon_intensity_stg (
    from_date VARCHAR(50) PRIMARY KEY,
    to_date VARCHAR(50) SORTKEY,
    intensity_max SMALLINT,
    intensity_average SMALLINT,
    intensity_min SMALLINT,
    intensity_index VARCHAR(50)
);, parameters: None
[2024-03-20T21:33:24.407+0000] {taskinstance.py:1400} INFO - Marking task as SUCCESS. dag_id=dag_carbon_intensity, task_id=create_stage_table_task, execution_date=20240318T000000, start_date=20240320T213245, end_date=20240320T213324
[2024-03-20T21:34:28.695+0000] {job.py:219} ERROR - Job heartbeat got an exception
Traceback (most recent call last):
  File "/home/airflow/.local/lib/python3.8/site-packages/sqlalchemy/engine/base.py", line 3371, in _wrap_pool_connect
    return fn()
  File "/home/airflow/.local/lib/python3.8/site-packages/sqlalchemy/pool/base.py", line 327, in connect
    return _ConnectionFairy._checkout(self)
  File "/home/airflow/.local/lib/python3.8/site-packages/sqlalchemy/pool/base.py", line 894, in _checkout
    fairy = _ConnectionRecord.checkout(pool)
  File "/home/airflow/.local/lib/python3.8/site-packages/sqlalchemy/pool/base.py", line 493, in checkout
    rec = pool._do_get()
  File "/home/airflow/.local/lib/python3.8/site-packages/sqlalchemy/pool/impl.py", line 256, in _do_get
    return self._create_connection()
  File "/home/airflow/.local/lib/python3.8/site-packages/sqlalchemy/pool/base.py", line 273, in _create_connection
    return _ConnectionRecord(self)
  File "/home/airflow/.local/lib/python3.8/site-packages/sqlalchemy/pool/base.py", line 388, in __init__
    self.__connect()
  File "/home/airflow/.local/lib/python3.8/site-packages/sqlalchemy/pool/base.py", line 691, in __connect
    pool.logger.debug("Error on connect(): %s", e)
  File "/home/airflow/.local/lib/python3.8/site-packages/sqlalchemy/util/langhelpers.py", line 70, in __exit__
    compat.raise_(
  File "/home/airflow/.local/lib/python3.8/site-packages/sqlalchemy/util/compat.py", line 211, in raise_
    raise exception
  File "/home/airflow/.local/lib/python3.8/site-packages/sqlalchemy/pool/base.py", line 686, in __connect
    self.dbapi_connection = connection = pool._invoke_creator(self)
  File "/home/airflow/.local/lib/python3.8/site-packages/sqlalchemy/engine/create.py", line 574, in connect
    return dialect.connect(*cargs, **cparams)
  File "/home/airflow/.local/lib/python3.8/site-packages/sqlalchemy/engine/default.py", line 598, in connect
    return self.dbapi.connect(*cargs, **cparams)
  File "/home/airflow/.local/lib/python3.8/site-packages/psycopg2/__init__.py", line 122, in connect
    conn = _connect(dsn, connection_factory=connection_factory, **kwasync)
psycopg2.OperationalError: could not translate host name "postgres" to address: Temporary failure in name resolution


The above exception was the direct cause of the following exception:

Traceback (most recent call last):
  File "/home/airflow/.local/lib/python3.8/site-packages/airflow/jobs/job.py", line 190, in heartbeat
    session.merge(self)
  File "/home/airflow/.local/lib/python3.8/site-packages/sqlalchemy/orm/session.py", line 3056, in merge
    return self._merge(
  File "/home/airflow/.local/lib/python3.8/site-packages/sqlalchemy/orm/session.py", line 3136, in _merge
    merged = self.get(
  File "/home/airflow/.local/lib/python3.8/site-packages/sqlalchemy/orm/session.py", line 2853, in get
    return self._get_impl(
  File "/home/airflow/.local/lib/python3.8/site-packages/sqlalchemy/orm/session.py", line 2975, in _get_impl
    return db_load_fn(
  File "/home/airflow/.local/lib/python3.8/site-packages/sqlalchemy/orm/loading.py", line 530, in load_on_pk_identity
    session.execute(
  File "/home/airflow/.local/lib/python3.8/site-packages/sqlalchemy/orm/session.py", line 1716, in execute
    conn = self._connection_for_bind(bind)
  File "/home/airflow/.local/lib/python3.8/site-packages/sqlalchemy/orm/session.py", line 1555, in _connection_for_bind
    return self._transaction._connection_for_bind(
  File "/home/airflow/.local/lib/python3.8/site-packages/sqlalchemy/orm/session.py", line 750, in _connection_for_bind
    conn = bind.connect()
  File "/home/airflow/.local/lib/python3.8/site-packages/sqlalchemy/future/engine.py", line 406, in connect
    return super(Engine, self).connect()
  File "/home/airflow/.local/lib/python3.8/site-packages/sqlalchemy/engine/base.py", line 3325, in connect
    return self._connection_cls(self, close_with_result=close_with_result)
  File "/home/airflow/.local/lib/python3.8/site-packages/sqlalchemy/engine/base.py", line 96, in __init__
    else engine.raw_connection()
  File "/home/airflow/.local/lib/python3.8/site-packages/sqlalchemy/engine/base.py", line 3404, in raw_connection
    return self._wrap_pool_connect(self.pool.connect, _connection)
  File "/home/airflow/.local/lib/python3.8/site-packages/sqlalchemy/engine/base.py", line 3374, in _wrap_pool_connect
    Connection._handle_dbapi_exception_noconnection(
  File "/home/airflow/.local/lib/python3.8/site-packages/sqlalchemy/engine/base.py", line 2208, in _handle_dbapi_exception_noconnection
    util.raise_(
  File "/home/airflow/.local/lib/python3.8/site-packages/sqlalchemy/util/compat.py", line 211, in raise_
    raise exception
  File "/home/airflow/.local/lib/python3.8/site-packages/sqlalchemy/engine/base.py", line 3371, in _wrap_pool_connect
    return fn()
  File "/home/airflow/.local/lib/python3.8/site-packages/sqlalchemy/pool/base.py", line 327, in connect
    return _ConnectionFairy._checkout(self)
  File "/home/airflow/.local/lib/python3.8/site-packages/sqlalchemy/pool/base.py", line 894, in _checkout
    fairy = _ConnectionRecord.checkout(pool)
  File "/home/airflow/.local/lib/python3.8/site-packages/sqlalchemy/pool/base.py", line 493, in checkout
    rec = pool._do_get()
  File "/home/airflow/.local/lib/python3.8/site-packages/sqlalchemy/pool/impl.py", line 256, in _do_get
    return self._create_connection()
  File "/home/airflow/.local/lib/python3.8/site-packages/sqlalchemy/pool/base.py", line 273, in _create_connection
    return _ConnectionRecord(self)
  File "/home/airflow/.local/lib/python3.8/site-packages/sqlalchemy/pool/base.py", line 388, in __init__
    self.__connect()
  File "/home/airflow/.local/lib/python3.8/site-packages/sqlalchemy/pool/base.py", line 691, in __connect
    pool.logger.debug("Error on connect(): %s", e)
  File "/home/airflow/.local/lib/python3.8/site-packages/sqlalchemy/util/langhelpers.py", line 70, in __exit__
    compat.raise_(
  File "/home/airflow/.local/lib/python3.8/site-packages/sqlalchemy/util/compat.py", line 211, in raise_
    raise exception
  File "/home/airflow/.local/lib/python3.8/site-packages/sqlalchemy/pool/base.py", line 686, in __connect
    self.dbapi_connection = connection = pool._invoke_creator(self)
  File "/home/airflow/.local/lib/python3.8/site-packages/sqlalchemy/engine/create.py", line 574, in connect
    return dialect.connect(*cargs, **cparams)
  File "/home/airflow/.local/lib/python3.8/site-packages/sqlalchemy/engine/default.py", line 598, in connect
    return self.dbapi.connect(*cargs, **cparams)
  File "/home/airflow/.local/lib/python3.8/site-packages/psycopg2/__init__.py", line 122, in connect
    conn = _connect(dsn, connection_factory=connection_factory, **kwasync)
sqlalchemy.exc.OperationalError: (psycopg2.OperationalError) could not translate host name "postgres" to address: Temporary failure in name resolution

(Background on this error at: https://sqlalche.me/e/14/e3q8)
[2024-03-20T21:34:58.018+0000] {local_task_job_runner.py:228} INFO - Task exited with return code 0
