[2024-03-10T16:38:10.613+0000] {logging_mixin.py:154} INFO - Changing /opt/***/logs/dag_id=dag_carbon_intensity/run_id=manual__2024-03-10T16:37:54.126396+00:00/task_id=load_data permission to 509
[2024-03-10T16:38:10.854+0000] {logging_mixin.py:154} INFO - Changing /opt/***/logs/dag_id=dag_carbon_intensity/run_id=manual__2024-03-10T16:37:54.126396+00:00/task_id=load_data permission to 509
[2024-03-10T16:38:10.940+0000] {taskinstance.py:1159} INFO - Dependencies all met for dep_context=non-requeueable deps ti=<TaskInstance: dag_carbon_intensity.load_data manual__2024-03-10T16:37:54.126396+00:00 [queued]>
[2024-03-10T16:38:10.957+0000] {taskinstance.py:1159} INFO - Dependencies all met for dep_context=requeueable deps ti=<TaskInstance: dag_carbon_intensity.load_data manual__2024-03-10T16:37:54.126396+00:00 [queued]>
[2024-03-10T16:38:10.959+0000] {taskinstance.py:1361} INFO - Starting attempt 1 of 4
[2024-03-10T16:38:10.982+0000] {taskinstance.py:1382} INFO - Executing <Task(PythonOperator): load_data> on 2024-03-10 16:37:54.126396+00:00
[2024-03-10T16:38:10.993+0000] {standard_task_runner.py:57} INFO - Started process 8296 to run task
[2024-03-10T16:38:11.004+0000] {standard_task_runner.py:84} INFO - Running: ['***', 'tasks', 'run', 'dag_carbon_intensity', 'load_data', 'manual__2024-03-10T16:37:54.126396+00:00', '--job-id', '151', '--raw', '--subdir', 'DAGS_FOLDER/dag_carbon_intensity.py', '--cfg-path', '/tmp/tmp72ije469']
[2024-03-10T16:38:11.008+0000] {standard_task_runner.py:85} INFO - Job 151: Subtask load_data
[2024-03-10T16:38:11.145+0000] {logging_mixin.py:154} INFO - Changing /opt/***/logs/dag_id=dag_carbon_intensity/run_id=manual__2024-03-10T16:37:54.126396+00:00/task_id=load_data permission to 509
[2024-03-10T16:38:11.187+0000] {task_command.py:416} INFO - Running <TaskInstance: dag_carbon_intensity.load_data manual__2024-03-10T16:37:54.126396+00:00 [running]> on host b90b2ddba1ac
[2024-03-10T16:38:11.472+0000] {taskinstance.py:1662} INFO - Exporting env vars: AIRFLOW_CTX_DAG_OWNER='***' AIRFLOW_CTX_DAG_ID='dag_carbon_intensity' AIRFLOW_CTX_TASK_ID='load_data' AIRFLOW_CTX_EXECUTION_DATE='2024-03-10T16:37:54.126396+00:00' AIRFLOW_CTX_TRY_NUMBER='1' AIRFLOW_CTX_DAG_RUN_ID='manual__2024-03-10T16:37:54.126396+00:00'
[2024-03-10T16:38:11.476+0000] {utils.py:65} ERROR - Error al obtener datos de https://api.carbonintensity.org.uk/intensity: unconverted data remains: +00:00
Traceback (most recent call last):
  File "/opt/airflow/scripts/utils.py", line 27, in get_data
    start = datetime.strptime(start, '%Y-%m-%dT%H:%M:%S')
  File "/usr/local/lib/python3.8/_strptime.py", line 568, in _strptime_datetime
    tt, fraction, gmtoff_fraction = _strptime(data_string, format)
  File "/usr/local/lib/python3.8/_strptime.py", line 352, in _strptime
    raise ValueError("unconverted data remains: %s" %
ValueError: unconverted data remains: +00:00
[2024-03-10T16:38:11.482+0000] {main_1.py:30} ERROR - Error al obtener datos de https://api.carbonintensity.org.uk/intensity: local variable 'df' referenced before assignment
[2024-03-10T16:38:11.483+0000] {taskinstance.py:1937} ERROR - Task failed with exception
Traceback (most recent call last):
  File "/home/airflow/.local/lib/python3.8/site-packages/airflow/operators/python.py", line 192, in execute
    return_value = self.execute_callable()
  File "/home/airflow/.local/lib/python3.8/site-packages/airflow/operators/python.py", line 209, in execute_callable
    return self.python_callable(*self.op_args, **self.op_kwargs)
  File "/opt/airflow/scripts/main_1.py", line 31, in load_carbon_intensity_data
    raise e
  File "/opt/airflow/scripts/main_1.py", line 21, in load_carbon_intensity_data
    df_carbon_intensity = get_data(base_url,
  File "/opt/airflow/scripts/utils.py", line 67, in get_data
    return df
UnboundLocalError: local variable 'df' referenced before assignment
[2024-03-10T16:38:11.517+0000] {taskinstance.py:1400} INFO - Marking task as UP_FOR_RETRY. dag_id=dag_carbon_intensity, task_id=load_data, execution_date=20240310T163754, start_date=20240310T163810, end_date=20240310T163811
[2024-03-10T16:38:11.544+0000] {standard_task_runner.py:104} ERROR - Failed to execute job 151 for task load_data (local variable 'df' referenced before assignment; 8296)
[2024-03-10T16:38:11.604+0000] {local_task_job_runner.py:228} INFO - Task exited with return code 1
[2024-03-10T16:38:11.655+0000] {taskinstance.py:2778} INFO - 0 downstream tasks scheduled from follow-on schedule check
